Workbook
Name Slicer_Category: #N/A
Name Slicer_Region: #N/A

Sheet Sheet6
A1: Row Labels | B1: Average of Price
A2: East | B2: 25441.372
A3: North | B3: 29128.17
A4: South | B4: 27442.176
A5: West | B5: 23523.964
A6: (blank) | B6: 7099.402
A7: Grand Total | B7: 25641.771
A26: Total sales by category and region | B26: Region
A27: Category | B27: East | C27: North | D27: South | E27: West | F27: (blank) | G27: Grand Total
A28: Beverages | B28: 15 | C28: 18 | D28: 17 | E28: 23 | G28: 73
A29: Clothing | B29: 23 | C29: 11 | D29: 10 | E29: 24 | G29: 68
A30: Electronics | B30: 15 | C30: 16 | D30: 21 | E30: 20 | G30: 72
A31: Food | B31: 19 | C31: 18 | D31: 14 | E31: 16 | G31: 67
A32: Furniture | B32: 28 | C32: 15 | D32: 14 | E32: 13 | G32: 70
A33: (blank)
A34: Grand Total | B34: 100 | C34: 78 | D34: 76 | E34: 96 | G34: 350

Sheet Dataset
A1: Order ID | B1: Region | C1: Country | D1: Category | E1: Sales Channel | F1: Order Priority | G1: Order Date | H1: Units Sold | I1: Unit Price | J1: Unit Cost | K1: Filled values in Region | L1: Filled value in Category | M1: Filled values in unit sold | N1: Filled values in unit price | O1: Total Revenue | P1: Price
A2: ORD0001 | B2: East | C2: Germany | D2: Beverages | E2: Online | F2: High | G2: 44927 | H2: 235 | I2: 152.92 | J2: 153.6 | K2: =IF(B2="", VLOOKUP(C2, Mapping!A:B, 2, FALSE), B2) -> East | L2: =IF(D2="", IF(H2<100,"Clothing", IF(H2<=250,"Food", IF(H2<=400,"Furniture","Electronics"))), D2) -> Beverages | M2: =IF(H2="", AVERAGEIF(Dataset!D:D, D2, Dataset!H:H), H2) -> 235 | N2: =IF(I2="", AVERAGEIF(Dataset!D:D, D2, Dataset!I:I), I2) -> 152.92 | O2: =IF(OR(H2="",I2=""),"",H2*I2) -> 35936.2 | P2: =MAX(0, H2*(I2-J2)) -> 0
A3: ORD0002 | B3: West | C3: India | D3: Food | E3: Online | F3: Low | G3: 44928 | H3: 341 | I3: 467.92 | J3: 139.84 | K3: =IF(B3="", VLOOKUP(C3, Mapping!A:B, 2, FALSE), B3) -> West | L3: =IF(D3="", IF(H3<100,"Clothing", IF(H3<=250,"Food", IF(H3<=400,"Furniture","Electronics"))), D3) -> Food | M3: =IF(H3="", AVERAGEIF(Dataset!D:D, D3, Dataset!H:H), H3) -> 341 | N3: =IF(I3="", AVERAGEIF(Dataset!D:D, D3, Dataset!I:I), I3) -> 467.92 | O3: =IF(OR(H3="",I3=""),"",H3*I3) -> 159560.72 | P3: =MAX(0, H3*(I3-J3)) -> 111875.28
A4: ORD0003 | B4: North | C4: India | D4: Clothing | E4: Offline | F4: High | G4: 44929 | H4: 179 | I4: 473.94 | J4: 97.14 | K4: =IF(B4="", VLOOKUP(C4, Mapping!A:B, 2, FALSE), B4) -> North | L4: =IF(D4="", IF(H4<100,"Clothing", IF(H4<=250,"Food", IF(H4<=400,"Furniture","Electronics"))), D4) -> Clothing | M4: =IF(H4="", AVERAGEIF(Dataset!D:D, D4, Dataset!H:H), H4) -> 179 | N4: =IF(I4="", AVERAGEIF(Dataset!D:D, D4, Dataset!I:I), I4) -> 473.94 | O4: =IF(OR(H4="",I4=""),"",H4*I4) -> 84835.26 | P4: =MAX(0, H4*(I4-J4)) -> 67447.2
A5: ORD0004 | B5: East | C5: USA | D5: Furniture | E5: Offline | F5: Medium | G5: 44930 | H5: 18 | I5: 314.53 | J5: 204.87 | K5: =IF(B5="", VLOOKUP(C5, Mapping!A:B, 2, FALSE), B5) -> East | L5: =IF(D5="", IF(H5<100,"Clothing", IF(H5<=250,"Food", IF(H5<=400,"Furniture","Electronics"))), D5) -> Furniture | M5: =IF(H5="", AVERAGEIF(Dataset!D:D, D5, Dataset!H:H), H5) -> 18 | N5: =IF(I5="", AVERAGEIF(Dataset!D:D, D5, Dataset!I:I), I5) -> 314.53 | O5: =IF(OR(H5="",I5=""),"",H5*I5) -> 5661.54 | P5: =MAX(0, H5*(I5-J5)) -> 1973.88
A6: ORD0005 | B6: East | C6: India | D6: Furniture | E6: Offline | F6: Medium | G6: 44931 | H6: 472 | I6: 392.79 | J6: 330.46 | K6: =IF(B6="", VLOOKUP(C6, Mapping!A:B, 2, FALSE), B6) -> East | L6: =IF(D6="", IF(H6<100,"Clothing", IF(H6<=250,"Food", IF(H6<=400,"Furniture","Electronics"))), D6) -> Furniture | M6: =IF(H6="", AVERAGEIF(Dataset!D:D, D6, Dataset!H:H), H6) -> 472 | N6: =IF(I6="", AVERAGEIF(Dataset!D:D, D6, Dataset!I:I), I6) -> 392.79 | O6: =IF(OR(H6="",I6=""),"",H6*I6) -> 185396.88 | P6: =MAX(0, H6*(I6-J6)) -> 29419.76
A7: ORD0006 | B7: West | C7: UK | D7: Clothing | E7: Online | F7: High | G7: 44932 | H7: 49 | I7: 308.07 | J7: 113.32 | K7: =IF(B7="", VLOOKUP(C7, Mapping!A:B, 2, FALSE), B7) -> West | L7: =IF(D7="", IF(H7<100,"Clothing", IF(H7<=250,"Food", IF(H7<=400,"Furniture","Electronics"))), D7) -> Clothing | M7: =IF(H7="", AVERAGEIF(Dataset!D:D, D7, Dataset!H:H), H7) -> 49 | N7: =IF(I7="", AVERAGEIF(Dataset!D:D, D7, Dataset!I:I), I7) -> 308.07 | O7: =IF(OR(H7="",I7=""),"",H7*I7) -> 15095.43 | P7: =MAX(0, H7*(I7-J7)) -> 9542.75
A8: ORD0007 | B8: North | C8: Germany | D8: Clothing | E8: Online | F8: Low | G8: 44933 | H8: 34 | I8: 244.78 | J8: 377.07 | K8: =IF(B8="", VLOOKUP(C8, Mapping!A:B, 2, FALSE), B8) -> North | L8: =IF(D8="", IF(H8<100,"Clothing", IF(H8<=250,"Food", IF(H8<=400,"Furniture","Electronics"))), D8) -> Clothing | M8: =IF(H8="", AVERAGEIF(Dataset!D:D, D8, Dataset!H:H), H8) -> 34 | N8: =IF(I8="", AVERAGEIF(Dataset!D:D, D8, Dataset!I:I), I8) -> 244.78 | O8: =IF(OR(H8="",I8=""),"",H8*I8) -> 8322.52 | P8: =MAX(0, H8*(I8-J8)) -> 0
A9: ORD0008 | B9: North | C9: India | D9: Beverages | E9: Online | F9: High | G9: 44934 | H9: 270 | I9: 332.11 | J9: 349.59 | K9: =IF(B9="", VLOOKUP(C9, Mapping!A:B, 2, FALSE), B9) -> North | L9: =IF(D9="", IF(H9<100,"Clothing", IF(H9<=250,"Food", IF(H9<=400,"Furniture","Electronics"))), D9) -> Beverages | M9: =IF(H9="", AVERAGEIF(Dataset!D:D, D9, Dataset!H:H), H9) -> 270 | N9: =IF(I9="", AVERAGEIF(Dataset!D:D, D9, Dataset!I:I), I9) -> 332.11 | O9: =IF(OR(H9="",I9=""),"",H9*I9) -> 89669.7 | P9: =MAX(0, H9*(I9-J9)) -> 0
A10: ORD0009 | B10: East | C10: India | D10: Beverages | E10: Online | F10: Low | G10: 44935 | H10: 404 | I10: 278.74 | J10: 66.38 | K10: =IF(B10="", VLOOKUP(C10, Mapping!A:B, 2, FALSE), B10) -> East | L10: =IF(D10="", IF(H10<100,"Clothing", IF(H10<=250,"Food", IF(H10<=400,"Furniture","Electronics"))), D10) -> Beverages | M10: =IF(H10="", AVERAGEIF(Dataset!D:D, D10, Dataset!H:H), H10) -> 404 | N10: =IF(I10="", AVERAGEIF(Dataset!D:D, D10, Dataset!I:I), I10) -> 278.74 | O10: =IF(OR(H10="",I10=""),"",H10*I10) -> 112610.96 | P10: =MAX(0, H10*(I10-J10)) -> 85793.44
A11: ORD0010 | C11: USA | D11: Furniture | E11: Online | F11: Medium | G11: 44936 | H11: 452 | I11: 300.75 | J11: 314.94 | K11: =IF(B11="", VLOOKUP(C11, Mapping!A:B, 2, FALSE), B11) -> East | L11: =IF(D11="", IF(H11<100,"Clothing", IF(H11<=250,"Food", IF(H11<=400,"Furniture","Electronics"))), D11) -> Furniture | M11: =IF(H11="", AVERAGEIF(Dataset!D:D, D11, Dataset!H:H), H11) -> 452 | N11: =IF(I11="", AVERAGEIF(Dataset!D:D, D11, Dataset!I:I), I11) -> 300.75 | O11: =IF(OR(H11="",I11=""),"",H11*I11) -> 135939 | P11: =MAX(0, H11*(I11-J11)) -> 0
A12: ORD0011 | B12: East | C12: USA | D12: Food | E12: Online | F12: Low | G12: 44937 | H12: 235 | I12: 393 | J12: 230.69 | K12: =IF(B12="", VLOOKUP(C12, Mapping!A:B, 2, FALSE), B12) -> East | L12: =IF(D12="", IF(H12<100,"Clothing", IF(H12<=250,"Food", IF(H12<=400,"Furniture","Electronics"))), D12) -> Food | M12: =IF(H12="", AVERAGEIF(Dataset!D:D, D12, Dataset!H:H), H12) -> 235 | N12: =IF(I12="", AVERAGEIF(Dataset!D:D, D12, Dataset!I:I), I12) -> 393 | O12: =IF(OR(H12="",I12=""),"",H12*I12) -> 92355 | P12: =MAX(0, H12*(I12-J12)) -> 38142.85
A13: ORD0012 | B13: East | C13: UK | D13: Furniture | E13: Offline | F13: Medium | G13: 44938 | H13: 481 | I13: 243.05 | J13: 227.5 | K13: =IF(B13="", VLOOKUP(C13, Mapping!A:B, 2, FALSE), B13) -> East | L13: =IF(D13="", IF(H13<100,"Clothing", IF(H13<=250,"Food", IF(H13<=400,"Furniture","Electronics"))), D13) -> Furniture | M13: =IF(H13="", AVERAGEIF(Dataset!D:D, D13, Dataset!H:H), H13) -> 481 | N13: =IF(I13="", AVERAGEIF(Dataset!D:D, D13, Dataset!I:I), I13) -> 243.05 | O13: =IF(OR(H13="",I13=""),"",H13*I13) -> 116907.05 | P13: =MAX(0, H13*(I13-J13)) -> 7479.55
A14: ORD0013 | B14: East | C14: Germany | D14: Food | E14: Offline | F14: Low | G14: 44939 | H14: 133 | I14: 25.17 | J14: 157.64 | K14: =IF(B14="", VLOOKUP(C14, Mapping!A:B, 2, FALSE), B14) -> East | L14: =IF(D14="", IF(H14<100,"Clothing", IF(H14<=250,"Food", IF(H14<=400,"Furniture","Electronics"))), D14) -> Food | M14: =IF(H14="", AVERAGEIF(Dataset!D:D, D14, Dataset!H:H), H14) -> 133 | N14: =IF(I14="", AVERAGEIF(Dataset!D:D, D14, Dataset!I:I), I14) -> 25.17 | O14: =IF(OR(H14="",I14=""),"",H14*I14) -> 3347.61 | P14: =MAX(0, H14*(I14-J14)) -> 0
A15: ORD0014 | B15: East | C15: USA | D15: Food | E15: Offline | F15: Low | G15: 44940 | H15: 472 | I15: 86.18 | J15: 201.46 | K15: =IF(B15="", VLOOKUP(C15, Mapping!A:B, 2, FALSE), B15) -> East | L15: =IF(D15="", IF(H15<100,"Clothing", IF(H15<=250,"Food", IF(H15<=400,"Furniture","Electronics"))), D15) -> Food | M15: =IF(H15="", AVERAGEIF(Dataset!D:D, D15, Dataset!H:H), H15) -> 472 | N15: =IF(I15="", AVERAGEIF(Dataset!D:D, D15, Dataset!I:I), I15) -> 86.18 | O15: =IF(OR(H15="",I15=""),"",H15*I15) -> 40676.96 | P15: =MAX(0, H15*(I15-J15)) -> 0
A16: ORD0015 | B16: West | C16: India | D16: Beverages | E16: Offline | F16: Low | G16: 44941 | H16: 47 | I16: 222.11 | J16: 160.08 | K16: =IF(B16="", VLOOKUP(C16, Mapping!A:B, 2, FALSE), B16) -> West | L16: =IF(D16="", IF(H16<100,"Clothing", IF(H16<=250,"Food", IF(H16<=400,"Furniture","Electronics"))), D16) -> Beverages | M16: =IF(H16="", AVERAGEIF(Dataset!D:D, D16, Dataset!H:H), H16) -> 47 | N16: =IF(I16="", AVERAGEIF(Dataset!D:D, D16, Dataset!I:I), I16) -> 222.11 | O16: =IF(OR(H16="",I16=""),"",H16*I16) -> 10439.17 | P16: =MAX(0, H16*(I16-J16)) -> 2915.41
A17: ORD0016 | B17: North | C17: Germany | D17: Electronics | E17: Online | F17: High | G17: 44942 | H17: 337 | I17: 363.79 | J17: 216.81 | K17: =IF(B17="", VLOOKUP(C17, Mapping!A:B, 2, FALSE), B17) -> North | L17: =IF(D17="", IF(H17<100,"Clothing", IF(H17<=250,"Food", IF(H17<=400,"Furniture","Electronics"))), D17) -> Electronics | M17: =IF(H17="", AVERAGEIF(Dataset!D:D, D17, Dataset!H:H), H17) -> 337 | N17: =IF(I17="", AVERAGEIF(Dataset!D:D, D17, Dataset!I:I), I17) -> 363.79 | O17: =IF(OR(H17="",I17=""),"",H17*I17) -> 122597.23 | P17: =MAX(0, H17*(I17-J17)) -> 49532.26
A18: ORD0017 | B18: West | C18: Germany | D18: Electronics | E18: Online | F18: High | G18: 44943 | H18: 260 | I18: 298.67 | J18: 251.92 | K18: =IF(B18="", VLOOKUP(C18, Mapping!A:B, 2, FALSE), B18) -> West | L18: =IF(D18="", IF(H18<100,"Clothing", IF(H18<=250,"Food", IF(H18<=400,"Furniture","Electronics"))), D18) -> Electronics | M18: =IF(H18="", AVERAGEIF(Dataset!D:D, D18, Dataset!H:H), H18) -> 260 | N18: =IF(I18="", AVERAGEIF(Dataset!D:D, D18, Dataset!I:I), I18) -> 298.67 | O18: =IF(OR(H18="",I18=""),"",H18*I18) -> 77654.2 | P18: =MAX(0, H18*(I18-J18)) -> 12155
A19: ORD0018 | C19: India | D19: Clothing | E19: Offline | F19: Medium | G19: 44944 | H19: 398 | I19: 326.9 | J19: 270.37 | K19: =IF(B19="", VLOOKUP(C19, Mapping!A:B, 2, FALSE), B19) -> East | L19: =IF(D19="", IF(H19<100,"Clothing", IF(H19<=250,"Food", IF(H19<=400,"Furniture","Electronics"))), D19) -> Clothing | M19: =IF(H19="", AVERAGEIF(Dataset!D:D, D19, Dataset!H:H), H19) -> 398 | N19: =IF(I19="", AVERAGEIF(Dataset!D:D, D19, Dataset!I:I), I19) -> 326.9 | O19: =IF(OR(H19="",I19=""),"",H19*I19) -> 130106.2 | P19: =MAX(0, H19*(I19-J19)) -> 22498.94
A20: ORD0019 | B20: West | C20: USA | D20: Beverages | E20: Online | F20: Medium | G20: 44945 | H20: 185 | I20: 242.24 | J20: 213.93 | K20: =IF(B20="", VLOOKUP(C20, Mapping!A:B, 2, FALSE), B20) -> West | L20: =IF(D20="", IF(H20<100,"Clothing", IF(H20<=250,"Food", IF(H20<=400,"Furniture","Electronics"))), D20) -> Beverages | M20: =IF(H20="", AVERAGEIF(Dataset!D:D, D20, Dataset!H:H), H20) -> 185 | N20: =IF(I20="", AVERAGEIF(Dataset!D:D, D20, Dataset!I:I), I20) -> 242.24 | O20: =IF(OR(H20="",I20=""),"",H20*I20) -> 44814.4 | P20: =MAX(0, H20*(I20-J20)) -> 5237.35
A21: ORD0020 | B21: East | C21: India | D21: Food | E21: Offline | F21: High | G21: 44946 | H21: 99 | I21: 309.79 | J21: 289.13 | K21: =IF(B21="", VLOOKUP(C21, Mapping!A:B, 2, FALSE), B21) -> East | L21: =IF(D21="", IF(H21<100,"Clothing", IF(H21<=250,"Food", IF(H21<=400,"Furniture","Electronics"))), D21) -> Food | M21: =IF(H21="", AVERAGEIF(Dataset!D:D, D21, Dataset!H:H), H21) -> 99 | N21: =IF(I21="", AVERAGEIF(Dataset!D:D, D21, Dataset!I:I), I21) -> 309.79 | O21: =IF(OR(H21="",I21=""),"",H21*I21) -> 30669.21 | P21: =MAX(0, H21*(I21-J21)) -> 2045.34
A22: ORD0021 | B22: South | C22: Germany | D22: Electronics | E22: Offline | F22: Medium | G22: 44947 | H22: 411 | I22: 167.86 | J22: 58.23 | K22: =IF(B22="", VLOOKUP(C22, Mapping!A:B, 2, FALSE), B22) -> South | L22: =IF(D22="", IF(H22<100,"Clothing", IF(H22<=250,"Food", IF(H22<=400,"Furniture","Electronics"))), D22) -> Electronics | M22: =IF(H22="", AVERAGEIF(Dataset!D:D, D22, Dataset!H:H), H22) -> 411 | N22: =IF(I22="", AVERAGEIF(Dataset!D:D, D22, Dataset!I:I), I22) -> 167.86 | O22: =IF(OR(H22="",I22=""),"",H22*I22) -> 68990.46 | P22: =MAX(0, H22*(I22-J22)) -> 45057.93
A23: ORD0022 | B23: North | C23: Australia | D23: Food | E23: Offline | F23: High | G23: 44948 | H23: 463 | I23: 237.74 | J23: 86.37 | K23: =IF(B23="", VLOOKUP(C23, Mapping!A:B, 2, FALSE), B23) -> North | L23: =IF(D23="", IF(H23<100,"Clothing", IF(H23<=250,"Food", IF(H23<=400,"Furniture","Electronics"))), D23) -> Food | M23: =IF(H23="", AVERAGEIF(Dataset!D:D, D23, Dataset!H:H), H23) -> 463 | N23: =IF(I23="", AVERAGEIF(Dataset!D:D, D23, Dataset!I:I), I23) -> 237.74 | O23: =IF(OR(H23="",I23=""),"",H23*I23) -> 110073.62 | P23: =MAX(0, H23*(I23-J23)) -> 70084.31
A24: ORD0023 | B24: South | C24: Australia | D24: Electronics | E24: Online | F24: Low | G24: 44949 | H24: 46 | I24: 373.42 | J24: 327.86 | K24: =IF(B24="", VLOOKUP(C24, Mapping!A:B, 2, FALSE), B24) -> South | L24: =IF(D24="", IF(H24<100,"Clothing", IF(H24<=250,"Food", IF(H24<=400,"Furniture","Electronics"))), D24) -> Electronics | M24: =IF(H24="", AVERAGEIF(Dataset!D:D, D24, Dataset!H:H), H24) -> 46 | N24: =IF(I24="", AVERAGEIF(Dataset!D:D, D24, Dataset!I:I), I24) -> 373.42 | O24: =IF(OR(H24="",I24=""),"",H24*I24) -> 17177.32 | P24: =MAX(0, H24*(I24-J24)) -> 2095.76
A25: ORD0024 | B25: West | C25: UK | D25: Electronics | E25: Offline | F25: Medium | G25: 44950 | H25: 325 | I25: 436.56 | J25: 130.37 | K25: =IF(B25="", VLOOKUP(C25, Mapping!A:B, 2, FALSE), B25) -> West | L25: =IF(D25="", IF(H25<100,"Clothing", IF(H25<=250,"Food", IF(H25<=400,"Furniture","Electronics"))), D25) -> Electronics | M25: =IF(H25="", AVERAGEIF(Dataset!D:D, D25, Dataset!H:H), H25) -> 325 | N25: =IF(I25="", AVERAGEIF(Dataset!D:D, D25, Dataset!I:I), I25) -> 436.56 | O25: =IF(OR(H25="",I25=""),"",H25*I25) -> 141882 | P25: =MAX(0, H25*(I25-J25)) -> 99511.75
A26: ORD0025 | B26: West | C26: India | E26: Offline | F26: Medium | G26: 44951 | H26: 185 | I26: 219.66 | J26: 11.11 | K26: =IF(B26="", VLOOKUP(C26, Mapping!A:B, 2, FALSE), B26) -> West | L26: =IF(D26="", IF(H26<100,"Clothing", IF(H26<=250,"Food", IF(H26<=400,"Furniture","Electronics"))), D26) -> Food | M26: =IF(H26="", AVERAGEIF(Dataset!D:D, D26, Dataset!H:H), H26) -> 185 | N26: =IF(I26="", AVERAGEIF(Dataset!D:D, D26, Dataset!I:I), I26) -> 219.66 | O26: =IF(OR(H26="",I26=""),"",H26*I26) -> 40637.1 | P26: =MAX(0, H26*(I26-J26)) -> 38581.75
A27: ORD0026 | B27: South | C27: India | D27: Beverages | E27: Offline | F27: High | G27: 44952 | H27: 470 | I27: 26.61 | J27: 63.21 | K27: =IF(B27="", VLOOKUP(C27, Mapping!A:B, 2, FALSE), B27) -> South | L27: =IF(D27="", IF(H27<100,"Clothing", IF(H27<=250,"Food", IF(H27<=400,"Furniture","Electronics"))), D27) -> Beverages | M27: =IF(H27="", AVERAGEIF(Dataset!D:D, D27, Dataset!H:H), H27) -> 470 | N27: =IF(I27="", AVERAGEIF(Dataset!D:D, D27, Dataset!I:I), I27) -> 26.61 | O27: =IF(OR(H27="",I27=""),"",H27*I27) -> 12506.7 | P27: =MAX(0, H27*(I27-J27)) -> 0
A28: ORD0027 | B28: South | C28: UK | D28: Furniture | E28: Online | F28: Medium | G28: 44953 | H28: 293 | I28: 85.03 | J28: 91 | K28: =IF(B28="", VLOOKUP(C28, Mapping!A:B, 2, FALSE), B28) -> South | L28: =IF(D28="", IF(H28<100,"Clothing", IF(H28<=250,"Food", IF(H28<=400,"Furniture","Electronics"))), D28) -> Furniture | M28: =IF(H28="", AVERAGEIF(Dataset!D:D, D28, Dataset!H:H), H28) -> 293 | N28: =IF(I28="", AVERAGEIF(Dataset!D:D, D28, Dataset!I:I), I28) -> 85.03 | O28: =IF(OR(H28="",I28=""),"",H28*I28) -> 24913.79 | P28: =MAX(0, H28*(I28-J28)) -> 0
A29: ORD0028 | B29: South | C29: UK | D29: Food | E29: Online | F29: Medium | G29: 44954 | H29: 462 | J29: 383.01 | K29: =IF(B29="", VLOOKUP(C29, Mapping!A:B, 2, FALSE), B29) -> South | L29: =IF(D29="", IF(H29<100,"Clothing", IF(H29<=250,"Food", IF(H29<=400,"Furniture","Electronics"))), D29) -> Food | M29: =IF(H29="", AVERAGEIF(Dataset!D:D, D29, Dataset!H:H), H29) -> 462 | N29: =IF(I29="", AVERAGEIF(Dataset!D:D, D29, Dataset!I:I), I29) -> 259.99929 | O29: =IF(OR(H29="",I29=""),"",H29*I29) | P29: =MAX(0, H29*(I29-J29)) -> 0
A30: ORD0029 | B30: West | C30: UK | D30: Beverages | E30: Offline | F30: Low | G30: 44955 | H30: 470 | I30: 328.37 | J30: 230.07 | K30: =IF(B30="", VLOOKUP(C30, Mapping!A:B, 2, FALSE), B30) -> West | L30: =IF(D30="", IF(H30<100,"Clothing", IF(H30<=250,"Food", IF(H30<=400,"Furniture","Electronics"))), D30) -> Beverages | M30: =IF(H30="", AVERAGEIF(Dataset!D:D, D30, Dataset!H:H), H30) -> 470 | N30: =IF(I30="", AVERAGEIF(Dataset!D:D, D30, Dataset!I:I), I30) -> 328.37 | O30: =IF(OR(H30="",I30=""),"",H30*I30) -> 154333.9 | P30: =MAX(0, H30*(I30-J30)) -> 46201
A31: ORD0030 | B31: West | C31: Germany | D31: Beverages | E31: Online | F31: Medium | G31: 44956 | H31: 90 | I31: 169.5 | J31: 373.23 | K31: =IF(B31="", VLOOKUP(C31, Mapping!A:B, 2, FALSE), B31) -> West | L31: =IF(D31="", IF(H31<100,"Clothing", IF(H31<=250,"Food", IF(H31<=400,"Furniture","Electronics"))), D31) -> Beverages | M31: =IF(H31="", AVERAGEIF(Dataset!D:D, D31, Dataset!H:H), H31) -> 90 | N31: =IF(I31="", AVERAGEIF(Dataset!D:D, D31, Dataset!I:I), I31) -> 169.5 | O31: =IF(OR(H31="",I31=""),"",H31*I31) -> 15255 | P31: =MAX(0, H31*(I31-J31)) -> 0
A32: ORD0031 | C32: India | D32: Beverages | E32: Online | F32: Low | G32: 44957 | H32: 123 | I32: 273.53 | J32: 230.92 | K32: =IF(B32="", VLOOKUP(C32, Mapping!A:B, 2, FALSE), B32) -> East | L32: =IF(D32="", IF(H32<100,"Clothing", IF(H32<=250,"Food", IF(H32<=400,"Furniture","Electronics"))), D32) -> Beverages | M32: =IF(H32="", AVERAGEIF(Dataset!D:D, D32, Dataset!H:H), H32) -> 123 | N32: =IF(I32="", AVERAGEIF(Dataset!D:D, D32, Dataset!I:I), I32) -> 273.53 | O32: =IF(OR(H32="",I32=""),"",H32*I32) -> 33644.19 | P32: =MAX(0, H32*(I32-J32)) -> 5241.03
A33: ORD0032 | B33: North | C33: Germany | D33: Beverages | E33: Online | F33: High | G33: 44958 | H33: 49 | I33: 249.17 | J33: 192.78 | K33: =IF(B33="", VLOOKUP(C33, Mapping!A:B, 2, FALSE), B33) -> North | L33: =IF(D33="", IF(H33<100,"Clothing", IF(H33<=250,"Food", IF(H33<=400,"Furniture","Electronics"))), D33) -> Beverages | M33: =IF(H33="", AVERAGEIF(Dataset!D:D, D33, Dataset!H:H), H33) -> 49 | N33: =IF(I33="", AVERAGEIF(Dataset!D:D, D33, Dataset!I:I), I33) -> 249.17 | O33: =IF(OR(H33="",I33=""),"",H33*I33) -> 12209.33 | P33: =MAX(0, H33*(I33-J33)) -> 2763.11
A34: ORD0033 | B34: West | C34: UK | D34: Beverages | E34: Online | F34: Medium | G34: 44959 | H34: 310 | I34: 45.36 | J34: 126.86 | K34: =IF(B34="", VLOOKUP(C34, Mapping!A:B, 2, FALSE), B34) -> West | L34: =IF(D34="", IF(H34<100,"Clothing", IF(H34<=250,"Food", IF(H34<=400,"Furniture","Electronics"))), D34) -> Beverages | M34: =IF(H34="", AVERAGEIF(Dataset!D:D, D34, Dataset!H:H), H34) -> 310 | N34: =IF(I34="", AVERAGEIF(Dataset!D:D, D34, Dataset!I:I), I34) -> 45.36 | O34: =IF(OR(H34="",I34=""),"",H34*I34) -> 14061.6 | P34: =MAX(0, H34*(I34-J34)) -> 0
A35: ORD0034 | B35: South | C35: India | D35: Clothing | E35: Online | F35: Low | G35: 44960 | H35: 233 | I35: 204.61 | J35: 243.34 | K35: =IF(B35="", VLOOKUP(C35, Mapping!A:B, 2, FALSE), B35) -> South | L35: =IF(D35="", IF(H35<100,"Clothing", IF(H35<=250,"Food", IF(H35<=400,"Furniture","Electronics"))), D35) -> Clothing | M35: =IF(H35="", AVERAGEIF(Dataset!D:D, D35, Dataset!H:H), H35) -> 233 | N35: =IF(I35="", AVERAGEIF(Dataset!D:D, D35, Dataset!I:I), I35) -> 204.61 | O35: =IF(OR(H35="",I35=""),"",H35*I35) -> 47674.13 | P35: =MAX(0, H35*(I35-J35)) -> 0
A36: ORD0035 | B36: South | C36: Germany | D36: Food | E36: Online | F36: High | G36: 44961 | H36: 327 | I36: 114.18 | J36: 57.4 | K36: =IF(B36="", VLOOKUP(C36, Mapping!A:B, 2, FALSE), B36) -> South | L36: =IF(D36="", IF(H36<100,"Clothing", IF(H36<=250,"Food", IF(H36<=400,"Furniture","Electronics"))), D36) -> Food | M36: =IF(H36="", AVERAGEIF(Dataset!D:D, D36, Dataset!H:H), H36) -> 327 | N36: =IF(I36="", AVERAGEIF(Dataset!D:D, D36, Dataset!I:I), I36) -> 114.18 | O36: =IF(OR(H36="",I36=""),"",H36*I36) -> 37336.86 | P36: =MAX(0, H36*(I36-J36)) -> 18567.06
A37: ORD0036 | B37: North | C37: Germany | D37: Beverages | E37: Online | F37: Medium | G37: 44962 | H37: 358 | I37: 212.11 | J37: 359.51 | K37: =IF(B37="", VLOOKUP(C37, Mapping!A:B, 2, FALSE), B37) -> North | L37: =IF(D37="", IF(H37<100,"Clothing", IF(H37<=250,"Food", IF(H37<=400,"Furniture","Electronics"))), D37) -> Beverages | M37: =IF(H37="", AVERAGEIF(Dataset!D:D, D37, Dataset!H:H), H37) -> 358 | N37: =IF(I37="", AVERAGEIF(Dataset!D:D, D37, Dataset!I:I), I37) -> 212.11 | O37: =IF(OR(H37="",I37=""),"",H37*I37) -> 75935.38 | P37: =MAX(0, H37*(I37-J37)) -> 0
A38: ORD0037 | B38: West | C38: UK | D38: Food | E38: Online | F38: High | G38: 44963 | H38: 124 | J38: 332.07 | K38: =IF(B38="", VLOOKUP(C38, Mapping!A:B, 2, FALSE), B38) -> West | L38: =IF(D38="", IF(H38<100,"Clothing", IF(H38<=250,"Food", IF(H38<=400,"Furniture","Electronics"))), D38) -> Food | M38: =IF(H38="", AVERAGEIF(Dataset!D:D, D38, Dataset!H:H), H38) -> 124 | N38: =IF(I38="", AVERAGEIF(Dataset!D:D, D38, Dataset!I:I), I38) -> 259.99929 | O38: =IF(OR(H38="",I38=""),"",H38*I38) | P38: =MAX(0, H38*(I38-J38)) -> 0
A39: ORD0038 | B39: North | C39: India | D39: Clothing | E39: Online | F39: Medium | G39: 44964 | H39: 195 | I39: 421.02 | J39: 128.38 | K39: =IF(B39="", VLOOKUP(C39, Mapping!A:B, 2, FALSE), B39) -> North | L39: =IF(D39="", IF(H39<100,"Clothing", IF(H39<=250,"Food", IF(H39<=400,"Furniture","Electronics"))), D39) -> Clothing | M39: =IF(H39="", AVERAGEIF(Dataset!D:D, D39, Dataset!H:H), H39) -> 195 | N39: =IF(I39="", AVERAGEIF(Dataset!D:D, D39, Dataset!I:I), I39) -> 421.02 | O39: =IF(OR(H39="",I39=""),"",H39*I39) -> 82098.9 | P39: =MAX(0, H39*(I39-J39)) -> 57064.8
A40: ORD0039 | B40: North | C40: UK | D40: Clothing | E40: Online | F40: High | G40: 44965 | I40: 91.23 | J40: 381.21 | K40: =IF(B40="", VLOOKUP(C40, Mapping!A:B, 2, FALSE), B40) -> North | L40: =IF(D40="", IF(H40<100,"Clothing", IF(H40<=250,"Food", IF(H40<=400,"Furniture","Electronics"))), D40) -> Clothing | M40: =IF(H40="", AVERAGEIF(Dataset!D:D, D40, Dataset!H:H), H40) -> 229.63077 | N40: =IF(I40="", AVERAGEIF(Dataset!D:D, D40, Dataset!I:I), I40) -> 91.23 | O40: =IF(OR(H40="",I40=""),"",H40*I40) | P40: =MAX(0, H40*(I40-J40)) -> 0
...

Sheet Mapping
A1: Country | B1: Region
A2: USA | B2: East
A3: India | B3: East
A4: Germany | B4: East
A5: UK | B5: West
A6: Australia | B6: South

Sheet Assignment
A1: Q1. Use Copilot to identify and summarize missing values in the dataset.
A3: Missing Values by Column
A4: Region: Missing in several rows (e.g., ORD0010, ORD0018, ORD0031, ORD0050, ORD0118, ORD0122, ORD0222, ORD0328, ORD0332, ORD0347).
A5: Category: Missing in rows like ORD0025, ORD0264, ORD0284, ORD0306, ORD0307, ORD0311, ORD0324.
A6: Units Sold: Missing in ORD0039, ORD0131, ORD0200, ORD0251, ORD0289, ORD0314, ORD0317.
A7: Unit Price: Missing in ORD0028, ORD0037, ORD0045, ORD0080, ORD0157, ORD0228, ORD0308, ORD0257.
A8: Unit Cost: Mostly present, but a few rows have suspiciously low values (e.g., ORD0168 = 6.15, ORD0248 = 210.62 with Unit Price = 6.28).
A10: Summary :
B11: Region column has the highest number of missing entries.
B12: Category is missing in multiple rows, which could affect product-level analysis.
B13: Units Sold and Unit Price have critical gaps — these directly impact revenue and profit calculations.
B14: Some rows have outliers or inconsistencies (e.g., Unit Price < Unit Cost, or extremely low values).
A17: Q2. Use Copilot to fill missing values in the Region and category columns.
A19: For filling missing value in Region column = IF(B2="", VLOOKUP(C2, Mapping!A:B, 2, FALSE), B2)
A20: For filling missing value in Category column = IF(D2="", IF(H2<100,"Clothing", IF(H2<=250,"Food", IF(H2<=400,"Furniture","Electronics"))), D2)
A22: Q3. Fill missing numeric values in the Unit Sold and Unit Price columns.
A24: For filling missing value in Unit sold column | F24: = IF(H2="", AVERAGEIF(Dataset!D:D, D2, Dataset!H:H), H2)
A25: For filling missing value in Unit price column | F25: = IF(I2="", AVERAGEIF(Dataset!D:D, D2, Dataset!I:I), I2)
A27: Q4. Create a new calculated column "Total revenue"
A29: Total Revenue = IF(OR(H2="",I2=""),"",H2*I2)
A31: Q5. Use Copilot to find the total price of Order ID = ‘ORD0123’.
B33: =VLOOKUP("ORD0123", Dataset!A:H, 8, FALSE) -> 46 | D33: Formula used by copilot= VLOOKUP("ORD0123", Dataset!A:H, 8, FALSE)
A35: Q6. Use Copilot to generate a summary chart of average profit by region.
A37: Step 1: Add a Profit Column
B38: Profit=Units Sold×(Unit Price−Unit Cost) | G38: present in sheet 6
A40: Formula used =MAX(0, H2*(I2-J2))
A42: Step 2: Create a PivotTable
B44: Select your dataset (including the new Profit column).
B45: Go to Insert → PivotTable.
B46: Place the PivotTable in a new sheet.
B47: Drag Region into the Rows area.
B48: Drag Profit into the Values area.
B49: Change the Value Field Settings to Average (instead of Sum).
A51: Step 3: Create a Chart
B53: 1. With the PivotTable selected, go to Insert → Column Chart (or Bar Chart).
B54: 2. This will give you a visual summary of average profit by region.
A57: Q7. Create a pivot table summarizing total sales by category and region
A59: Step 1: Add a “Total Sales” Column
B60: In your Dataset sheet, insert a new column called Total Revenue
B61: Formula used = =IF(OR(H2="",I2=""),"",H2*I2)
...

Sheet Dashboard
A2: Category | B2: Total sales by category | D2: Region | E2: Total sales by Region
A3: Beverages | B3: 4853531.9 | D3: East | E3: 6484450
A4: Clothing | B4: 3684276.4 | D4: North | E4: 5062600.7
A5: Electronics | B5: 4519876.1 | D5: South | E5: 4006353.3
A6: Food | B6: 3874198.4 | D6: West | E6: 5828221
A7: Furniture | B7: 4449742.1 | D7: (blank)
A8: (blank) | D8: Grand Total | E8: 21381625
A9: Grand Total | B9: 21381625
A12: Region | B12: Avg profit by Region | F12: Order ID | G12: Top 5 orders by revenue
A13: East | B13: 23861.589 | F13: ORD0334 | G13: 239220.11
A14: North | B14: 29128.17 | F14: ORD0231 | G14: 235447.36
A15: South | B15: 27081.095 | F15: ORD0142 | G15: 232738.38
A16: West | B16: 23523.964 | F16: ORD0156 | G16: 220772.37
A17: (blank) | F17: ORD0165 | G17: 220534.8
A18: Grand Total | B18: 25641.771 | F18: Grand Total | G18: 1148713
